<?xml version='1.0' encoding='UTF-8'?>
<robot xmlns:xacro="http://www.ros.org/wiki/xacro">
	<xacro:macro name="denso_robot_arm_kinematics" params="namespace model">
		<link name="world"/>
		<joint name="$(arg namespace)joint_w" type="fixed">
			<parent link="world"/>
			<child link="$(arg namespace)base_link"/>
		</joint>
		<link name="$(arg namespace)base_link">
			<visual>
				<origin rpy="0 0 0" xyz="0 0 0"/>
				<geometry>
					<mesh filename="file:///$(find denso_robot_descriptions)/robots/$(arg model)/meshes/base_link.dae" scale="1 1 1"/>
				</geometry>
			</visual>
			<collision>
				<origin rpy="0 0 0" xyz="0 0 0"/>
				<geometry>
					<mesh filename="file:///$(find denso_robot_descriptions)/robots/$(arg model)/meshes/base_link.dae" scale="1 1 1"/>
				</geometry>
			</collision>
			<inertial>
				<mass value="1"/>
				<origin rpy="0.000000 0.000000 0.000000" xyz="0.000000 0.000000 0.000000"/>
				<inertia ixx="1" ixy="0" ixz="0" iyy="1" iyz="0" izz="1"/>
			</inertial>
		</link>
		<link name="$(arg namespace)J1">
			<visual>
				<origin rpy="0 0 0" xyz="0 0 0"/>
				<geometry>
					<mesh filename="file:///$(find denso_robot_descriptions)/robots/$(arg model)/meshes/J1.dae" scale="1 1 1"/>
				</geometry>
			</visual>
			<collision>
				<origin rpy="0 0 0" xyz="0 0 0"/>
				<geometry>
					<mesh filename="file:///$(find denso_robot_descriptions)/robots/$(arg model)/meshes/J1.dae" scale="1 1 1"/>
				</geometry>
			</collision>
			<inertial>
				<mass value="1"/>
				<origin rpy="0.000000 0.000000 0.000000" xyz="0.000000 0.000000 0.000000"/>
				<inertia ixx="1" ixy="0" ixz="0" iyy="1" iyz="0" izz="1"/>
			</inertial>
		</link>
		<joint name="$(arg namespace)joint_1" type="revolute">
			<parent link="$(arg namespace)base_link"/>
			<child link="$(arg namespace)J1"/>
			<origin rpy="0.000000 0.000000 0.000000" xyz="0.000000 0.000000 0.181500"/>
			<axis xyz="-0.000000 -0.000000 1.000000"/>
			<limit effort="1" lower="-2.96705972839036" upper="2.96705972839036" velocity="3.73064127613788"/>
			<dynamics damping="0" friction="0"/>
		</joint>
		<link name="$(arg namespace)J2">
			<visual>
				<origin rpy="0 0 0" xyz="0 0 0"/>
				<geometry>
					<mesh filename="file:///$(find denso_robot_descriptions)/robots/$(arg model)/meshes/J2.dae" scale="1 1 1"/>
				</geometry>
			</visual>
			<collision>
				<origin rpy="0 0 0" xyz="0 0 0"/>
				<geometry>
					<mesh filename="file:///$(find denso_robot_descriptions)/robots/$(arg model)/meshes/J2.dae" scale="1 1 1"/>
				</geometry>
			</collision>
			<inertial>
				<mass value="1"/>
				<origin rpy="0.000000 0.000000 0.000000" xyz="0.000000 0.000000 0.000000"/>
				<inertia ixx="1" ixy="0" ixz="0" iyy="1" iyz="0" izz="1"/>
			</inertial>
		</link>
		<joint name="$(arg namespace)joint_2" type="revolute">
			<parent link="$(arg namespace)J1"/>
			<child link="$(arg namespace)J2"/>
			<origin rpy="0.000000 0.000000 0.000000" xyz="0.000000 0.000000 0.163500"/>
			<axis xyz="-0.000000 1.000000 -0.000000"/>
			<limit effort="1" lower="-2.0943951023932" upper="2.0943951023932" velocity="2.48709418409192"/>
			<dynamics damping="0" friction="0"/>
		</joint>
		<link name="$(arg namespace)J3">
			<visual>
				<origin rpy="0 0 0" xyz="0 0 0"/>
				<geometry>
					<mesh filename="file:///$(find denso_robot_descriptions)/robots/$(arg model)/meshes/J3.dae" scale="1 1 1"/>
				</geometry>
			</visual>
			<collision>
				<origin rpy="0 0 0" xyz="0 0 0"/>
				<geometry>
					<mesh filename="file:///$(find denso_robot_descriptions)/robots/$(arg model)/meshes/J3.dae" scale="1 1 1"/>
				</geometry>
			</collision>
			<inertial>
				<mass value="1"/>
				<origin rpy="0.000000 0.000000 0.000000" xyz="0.000000 0.000000 0.000000"/>
				<inertia ixx="1" ixy="0" ixz="0" iyy="1" iyz="0" izz="1"/>
			</inertial>
		</link>
		<joint name="$(arg namespace)joint_3" type="revolute">
			<parent link="$(arg namespace)J2"/>
			<child link="$(arg namespace)J3"/>
			<origin rpy="0.000000 0.000000 0.000000" xyz="0.000000 0.000000 0.305000"/>
			<axis xyz="-0.000000 1.000000 -0.000000"/>
			<limit effort="1" lower="-2.18166156499291" upper="2.70526034059121" velocity="2.71540943019156"/>
			<dynamics damping="0" friction="0"/>
		</joint>
		<link name="$(arg namespace)J4">
			<visual>
				<origin rpy="0 0 0" xyz="0 0 0"/>
				<geometry>
					<mesh filename="file:///$(find denso_robot_descriptions)/robots/$(arg model)/meshes/J4.dae" scale="1 1 1"/>
				</geometry>
			</visual>
			<collision>
				<origin rpy="0 0 0" xyz="0 0 0"/>
				<geometry>
					<mesh filename="file:///$(find denso_robot_descriptions)/robots/$(arg model)/meshes/J4.dae" scale="1 1 1"/>
				</geometry>
			</collision>
			<inertial>
				<mass value="1"/>
				<origin rpy="0.000000 0.000000 0.000000" xyz="0.000000 0.000000 0.000000"/>
				<inertia ixx="1" ixy="0" ixz="0" iyy="1" iyz="0" izz="1"/>
			</inertial>
		</link>
		<joint name="$(arg namespace)joint_4" type="revolute">
			<parent link="$(arg namespace)J3"/>
			<child link="$(arg namespace)J4"/>
			<origin rpy="0.000000 0.000000 0.000000" xyz="-0.010000 0.000000 0.164500"/>
			<axis xyz="-0.000000 -0.000000 1.000000"/>
			<limit effort="1" lower="-4.71238898038469" upper="4.71238898038469" velocity="3.73064127613788"/>
			<dynamics damping="0" friction="0"/>
		</joint>
		<link name="$(arg namespace)J5">
			<visual>
				<origin rpy="0 0 0" xyz="0 0 0"/>
				<geometry>
					<mesh filename="file:///$(find denso_robot_descriptions)/robots/$(arg model)/meshes/J5.dae" scale="1 1 1"/>
				</geometry>
			</visual>
			<collision>
				<origin rpy="0 0 0" xyz="0 0 0"/>
				<geometry>
					<mesh filename="file:///$(find denso_robot_descriptions)/robots/$(arg model)/meshes/J5.dae" scale="1 1 1"/>
				</geometry>
			</collision>
			<inertial>
				<mass value="1"/>
				<origin rpy="0.000000 0.000000 0.000000" xyz="0.000000 0.000000 0.000000"/>
				<inertia ixx="1" ixy="0" ixz="0" iyy="1" iyz="0" izz="1"/>
			</inertial>
		</link>
		<joint name="$(arg namespace)joint_5" type="revolute">
			<parent link="$(arg namespace)J4"/>
			<child link="$(arg namespace)J5"/>
			<origin rpy="0.000000 0.000000 0.000000" xyz="0.000000 0.000000 0.135500"/>
			<axis xyz="-0.000000 1.000000 -0.000000"/>
			<limit effort="1" lower="-2.0943951023932" upper="2.0943951023932" velocity="2.87060410727889"/>
			<dynamics damping="0" friction="0"/>
		</joint>
		<link name="$(arg namespace)J6">
			<visual>
				<origin rpy="0 0 0" xyz="0 0 0"/>
				<geometry>
					<mesh filename="file:///$(find denso_robot_descriptions)/robots/$(arg model)/meshes/J6.dae" scale="1 1 1"/>
				</geometry>
			</visual>
			<collision>
				<origin rpy="0 0 0" xyz="0 0 0"/>
				<geometry>
					<mesh filename="file:///$(find denso_robot_descriptions)/robots/$(arg model)/meshes/J6.dae" scale="1 1 1"/>
				</geometry>
			</collision>
			<inertial>
				<mass value="1"/>
				<origin rpy="0.000000 0.000000 0.000000" xyz="0.000000 0.000000 0.000000"/>
				<inertia ixx="1" ixy="0" ixz="0" iyy="1" iyz="0" izz="1"/>
			</inertial>
		</link>
		<joint name="$(arg namespace)joint_6" type="revolute">
			<parent link="$(arg namespace)J5"/>
			<child link="$(arg namespace)J6"/>
			<origin rpy="0.000000 0.000000 0.000000" xyz="0.000000 0.000000 0.070000"/>
			<axis xyz="-0.000000 -0.000000 1.000000"/>
			<limit effort="1" lower="-6.28318530717959" upper="6.28318530717959" velocity="5.96902604182061"/>
			<dynamics damping="0" friction="0"/>
		</joint>
	</xacro:macro>
</robot>